Loaded module: python3/3.6.2
You are using pip version 9.0.1, however version 20.1.1 is available.
You should consider upgrading via the 'pip install --upgrade pip' command.
/zhome/bd/0/137202/.local/lib/python3.6/site-packages/tensorflow/python/framework/dtypes.py:516: FutureWarning: Passing (type, 1) or '1type' as a synonym of type is deprecated; in a future version of numpy, it will be understood as (type, (1,)) / '(1,)type'.
  _np_qint8 = np.dtype([("qint8", np.int8, 1)])
/zhome/bd/0/137202/.local/lib/python3.6/site-packages/tensorflow/python/framework/dtypes.py:517: FutureWarning: Passing (type, 1) or '1type' as a synonym of type is deprecated; in a future version of numpy, it will be understood as (type, (1,)) / '(1,)type'.
  _np_quint8 = np.dtype([("quint8", np.uint8, 1)])
/zhome/bd/0/137202/.local/lib/python3.6/site-packages/tensorflow/python/framework/dtypes.py:518: FutureWarning: Passing (type, 1) or '1type' as a synonym of type is deprecated; in a future version of numpy, it will be understood as (type, (1,)) / '(1,)type'.
  _np_qint16 = np.dtype([("qint16", np.int16, 1)])
/zhome/bd/0/137202/.local/lib/python3.6/site-packages/tensorflow/python/framework/dtypes.py:519: FutureWarning: Passing (type, 1) or '1type' as a synonym of type is deprecated; in a future version of numpy, it will be understood as (type, (1,)) / '(1,)type'.
  _np_quint16 = np.dtype([("quint16", np.uint16, 1)])
/zhome/bd/0/137202/.local/lib/python3.6/site-packages/tensorflow/python/framework/dtypes.py:520: FutureWarning: Passing (type, 1) or '1type' as a synonym of type is deprecated; in a future version of numpy, it will be understood as (type, (1,)) / '(1,)type'.
  _np_qint32 = np.dtype([("qint32", np.int32, 1)])
/zhome/bd/0/137202/.local/lib/python3.6/site-packages/tensorflow/python/framework/dtypes.py:525: FutureWarning: Passing (type, 1) or '1type' as a synonym of type is deprecated; in a future version of numpy, it will be understood as (type, (1,)) / '(1,)type'.
  np_resource = np.dtype([("resource", np.ubyte, 1)])
/zhome/bd/0/137202/.local/lib/python3.6/site-packages/tensorboard/compat/tensorflow_stub/dtypes.py:541: FutureWarning: Passing (type, 1) or '1type' as a synonym of type is deprecated; in a future version of numpy, it will be understood as (type, (1,)) / '(1,)type'.
  _np_qint8 = np.dtype([("qint8", np.int8, 1)])
/zhome/bd/0/137202/.local/lib/python3.6/site-packages/tensorboard/compat/tensorflow_stub/dtypes.py:542: FutureWarning: Passing (type, 1) or '1type' as a synonym of type is deprecated; in a future version of numpy, it will be understood as (type, (1,)) / '(1,)type'.
  _np_quint8 = np.dtype([("quint8", np.uint8, 1)])
/zhome/bd/0/137202/.local/lib/python3.6/site-packages/tensorboard/compat/tensorflow_stub/dtypes.py:543: FutureWarning: Passing (type, 1) or '1type' as a synonym of type is deprecated; in a future version of numpy, it will be understood as (type, (1,)) / '(1,)type'.
  _np_qint16 = np.dtype([("qint16", np.int16, 1)])
/zhome/bd/0/137202/.local/lib/python3.6/site-packages/tensorboard/compat/tensorflow_stub/dtypes.py:544: FutureWarning: Passing (type, 1) or '1type' as a synonym of type is deprecated; in a future version of numpy, it will be understood as (type, (1,)) / '(1,)type'.
  _np_quint16 = np.dtype([("quint16", np.uint16, 1)])
/zhome/bd/0/137202/.local/lib/python3.6/site-packages/tensorboard/compat/tensorflow_stub/dtypes.py:545: FutureWarning: Passing (type, 1) or '1type' as a synonym of type is deprecated; in a future version of numpy, it will be understood as (type, (1,)) / '(1,)type'.
  _np_qint32 = np.dtype([("qint32", np.int32, 1)])
/zhome/bd/0/137202/.local/lib/python3.6/site-packages/tensorboard/compat/tensorflow_stub/dtypes.py:550: FutureWarning: Passing (type, 1) or '1type' as a synonym of type is deprecated; in a future version of numpy, it will be understood as (type, (1,)) / '(1,)type'.
  np_resource = np.dtype([("resource", np.ubyte, 1)])
/zhome/bd/0/137202/.local/lib/python3.6/site-packages/librosa/core/audio.py:161: UserWarning: PySoundFile failed. Trying audioread instead.
  warnings.warn('PySoundFile failed. Trying audioread instead.')
Traceback (most recent call last):
  File "/zhome/bd/0/137202/.local/lib/python3.6/site-packages/librosa/core/audio.py", line 129, in load
    with sf.SoundFile(path) as sf_desc:
  File "/zhome/bd/0/137202/.local/lib/python3.6/site-packages/soundfile.py", line 629, in __init__
    self._file = self._open(file, mode_int, closefd)
  File "/zhome/bd/0/137202/.local/lib/python3.6/site-packages/soundfile.py", line 1184, in _open
    "Error opening {0!r}: ".format(self.name))
  File "/zhome/bd/0/137202/.local/lib/python3.6/site-packages/soundfile.py", line 1357, in _error_check
    raise RuntimeError(prefix + _ffi.string(err_str).decode('utf-8', 'replace'))
RuntimeError: Error opening '/work1/s183921/speaker_data/Spraakbanken-Corpus/Stasjon03_180700_r5650047/u0047200.wav': File contains data in an unknown format.

During handling of the above exception, another exception occurred:

Traceback (most recent call last):
  File "dataset/make.py", line 121, in <module>
    mel, mag = spec_feature_extraction(path)
  File "dataset/make.py", line 63, in spec_feature_extraction
    mel, mag = get_spectrograms(wav_file)
  File "/work1/s183921/fagprojekt2020/preprocess/spraakbanken/vae/dataset/tacotron/utils.py", line 34, in get_spectrograms
    y, sr = librosa.load(fpath, sr=hp.sr)
  File "/zhome/bd/0/137202/.local/lib/python3.6/site-packages/librosa/core/audio.py", line 162, in load
    y, sr_native = __audioread_load(path, offset, duration, dtype)
  File "/zhome/bd/0/137202/.local/lib/python3.6/site-packages/librosa/core/audio.py", line 186, in __audioread_load
    with audioread.audio_open(path) as input_file:
  File "/zhome/bd/0/137202/.local/lib/python3.6/site-packages/audioread/__init__.py", line 116, in audio_open
    raise NoBackendError()
audioread.exceptions.NoBackendError
Traceback (most recent call last):
  File "dataset/reduce.py", line 9, in <module>
    with open(pkl_path, 'rb') as f:
FileNotFoundError: [Errno 2] No such file or directory: '/work1/s183921/preprocessed_data/vae/spraakbanken/train.pkl'
Traceback (most recent call last):
  File "dataset/segments.py", line 13, in <module>
    with open(pickle_path, 'rb') as f:
FileNotFoundError: [Errno 2] No such file or directory: '/work1/s183921/preprocessed_data/vae/spraakbanken/train.pkl'
Traceback (most recent call last):
  File "dataset/segments.py", line 13, in <module>
    with open(pickle_path, 'rb') as f:
FileNotFoundError: [Errno 2] No such file or directory: '/work1/s183921/preprocessed_data/vae/spraakbanken/in_test.pkl'
Traceback (most recent call last):
  File "dataset/segments.py", line 13, in <module>
    with open(pickle_path, 'rb') as f:
FileNotFoundError: [Errno 2] No such file or directory: '/work1/s183921/preprocessed_data/vae/spraakbanken/out_test.pkl'
